[2024-04-20T09:14:32.676+0000] {task_context_logger.py:104} ERROR - Executor reports task instance <TaskInstance: wikipedia_flow.transform_wikipedia_data manual__2024-04-20T09:14:17.663076+00:00 [queued]> finished (failed) although the task says it's queued. (Info: None) Was the task killed externally?
