[2024-05-17T00:54:22.189+0000] {local_task_job_runner.py:120} INFO - ::group::Pre task execution logs
[2024-05-17T00:54:22.234+0000] {taskinstance.py:2073} INFO - Dependencies all met for dep_context=non-requeueable deps ti=<TaskInstance: wikipedia_flow.transform_wikipedia_data manual__2024-05-17T00:53:58.923977+00:00 [queued]>
[2024-05-17T00:54:22.257+0000] {taskinstance.py:2073} INFO - Dependencies all met for dep_context=requeueable deps ti=<TaskInstance: wikipedia_flow.transform_wikipedia_data manual__2024-05-17T00:53:58.923977+00:00 [queued]>
[2024-05-17T00:54:22.259+0000] {taskinstance.py:2303} INFO - Starting attempt 1 of 1
[2024-05-17T00:54:22.293+0000] {taskinstance.py:2327} INFO - Executing <Task(PythonOperator): transform_wikipedia_data> on 2024-05-17 00:53:58.923977+00:00
[2024-05-17T00:54:22.306+0000] {warnings.py:110} WARNING - /home/***/.local/lib/python3.12/site-packages/***/task/task_runner/standard_task_runner.py:61: DeprecationWarning: This process (pid=144) is multi-threaded, use of fork() may lead to deadlocks in the child.
  pid = os.fork()

[2024-05-17T00:54:22.309+0000] {standard_task_runner.py:63} INFO - Started process 146 to run task
[2024-05-17T00:54:22.310+0000] {standard_task_runner.py:90} INFO - Running: ['***', 'tasks', 'run', 'wikipedia_flow', 'transform_wikipedia_data', 'manual__2024-05-17T00:53:58.923977+00:00', '--job-id', '62', '--raw', '--subdir', 'DAGS_FOLDER/wikipedia_flow.py', '--cfg-path', '/tmp/tmpgs24w0y4']
[2024-05-17T00:54:22.312+0000] {standard_task_runner.py:91} INFO - Job 62: Subtask transform_wikipedia_data
[2024-05-17T00:54:22.413+0000] {task_command.py:426} INFO - Running <TaskInstance: wikipedia_flow.transform_wikipedia_data manual__2024-05-17T00:53:58.923977+00:00 [running]> on host 85d72ecba59d
[2024-05-17T00:54:22.565+0000] {taskinstance.py:2644} INFO - Exporting env vars: AIRFLOW_CTX_DAG_OWNER='Yusuf Ganiyu' AIRFLOW_CTX_DAG_ID='wikipedia_flow' AIRFLOW_CTX_TASK_ID='transform_wikipedia_data' AIRFLOW_CTX_EXECUTION_DATE='2024-05-17T00:53:58.923977+00:00' AIRFLOW_CTX_TRY_NUMBER='1' AIRFLOW_CTX_DAG_RUN_ID='manual__2024-05-17T00:53:58.923977+00:00'
[2024-05-17T00:54:22.568+0000] {taskinstance.py:430} INFO - ::endgroup::
[2024-05-17T00:58:04.695+0000] {connectionpool.py:824} WARNING - Retrying (Retry(total=1, connect=None, read=None, redirect=None, status=None)) after connection broken by 'ReadTimeoutError("HTTPSConnectionPool(host='nominatim.openstreetmap.org', port=443): Read timed out. (read timeout=10)")': /search?q=Castel%C3%A3o%2C+Brazil&format=json&limit=1
[2024-05-17T01:08:02.515+0000] {warnings.py:110} WARNING - /opt/***/pipelines/wikipedia_pipeline.py:100: SettingWithCopyWarning: 
A value is trying to be set on a copy of a slice from a DataFrame.
Try using .loc[row_indexer,col_indexer] = value instead

See the caveats in the documentation: https://pandas.pydata.org/pandas-docs/stable/user_guide/indexing.html#returning-a-view-versus-a-copy
  duplicates['location'] = duplicates.apply(lambda x: get_lat_long(x['country'], x['city']), axis=1)

[2024-05-17T01:08:02.636+0000] {taskinstance.py:441} INFO - ::group::Post task execution logs
[2024-05-17T01:08:02.674+0000] {taskinstance.py:2890} ERROR - Task failed with exception
Traceback (most recent call last):
  File "/home/airflow/.local/lib/python3.12/site-packages/airflow/models/taskinstance.py", line 465, in _execute_task
    result = _execute_callable(context=context, **execute_callable_kwargs)
             ^^^^^^^^^^^^^^^^^^^^^^^^^^^^^^^^^^^^^^^^^^^^^^^^^^^^^^^^^^^^^
  File "/home/airflow/.local/lib/python3.12/site-packages/airflow/models/taskinstance.py", line 432, in _execute_callable
    return execute_callable(context=context, **execute_callable_kwargs)
           ^^^^^^^^^^^^^^^^^^^^^^^^^^^^^^^^^^^^^^^^^^^^^^^^^^^^^^^^^^^^
  File "/home/airflow/.local/lib/python3.12/site-packages/airflow/models/baseoperator.py", line 400, in wrapper
    return func(self, *args, **kwargs)
           ^^^^^^^^^^^^^^^^^^^^^^^^^^^
  File "/home/airflow/.local/lib/python3.12/site-packages/airflow/operators/python.py", line 235, in execute
    return_value = self.execute_callable()
                   ^^^^^^^^^^^^^^^^^^^^^^^
  File "/home/airflow/.local/lib/python3.12/site-packages/airflow/operators/python.py", line 252, in execute_callable
    return self.python_callable(*self.op_args, **self.op_kwargs)
           ^^^^^^^^^^^^^^^^^^^^^^^^^^^^^^^^^^^^^^^^^^^^^^^^^^^^^
  File "/opt/airflow/pipelines/wikipedia_pipeline.py", line 115, in transform_wikipedia_data
    longtitude.append(tam[i].split(',')[0].split('[')[1])
                      ~~~~~~~~~~~~~~~~~~~~~~~~~~~~~~~^^^
IndexError: list index out of range
[2024-05-17T01:08:02.893+0000] {taskinstance.py:1205} INFO - Marking task as FAILED. dag_id=wikipedia_flow, task_id=transform_wikipedia_data, execution_date=20240517T005358, start_date=20240517T005422, end_date=20240517T010802
[2024-05-17T01:08:03.074+0000] {standard_task_runner.py:110} ERROR - Failed to execute job 62 for task transform_wikipedia_data (list index out of range; 146)
[2024-05-17T01:08:03.182+0000] {local_task_job_runner.py:240} INFO - Task exited with return code 1
[2024-05-17T01:08:03.388+0000] {taskinstance.py:3482} INFO - 0 downstream tasks scheduled from follow-on schedule check
[2024-05-17T01:08:03.407+0000] {local_task_job_runner.py:222} INFO - ::endgroup::
