[2024-04-28T14:58:23.190+0000] {task_context_logger.py:104} ERROR - Executor reports task instance <TaskInstance: wikipedia_flow.extract_data_from_wikipedia manual__2024-04-28T14:58:19.077111+00:00 [queued]> finished (failed) although the task says it's queued. (Info: None) Was the task killed externally?
